

2021-12-15 21:26:42,855 ERROR    [<ipython-input-3-d160bc6ff1e6>:81] Message: no such window: target window already closed
from unknown error: web view not found
  (Session info: chrome=96.0.4664.110)
Traceback (most recent call last):
  File "<ipython-input-3-d160bc6ff1e6>", line 74, in __bypass_cookies
    WebDriverWait(self.driver, 10).until(
  File "/Users/dan/opt/miniconda3/envs/AICore/lib/python3.9/site-packages/selenium/webdriver/support/wait.py", line 71, in until
    value = method(self._driver)
  File "/Users/dan/opt/miniconda3/envs/AICore/lib/python3.9/site-packages/selenium/webdriver/support/expected_conditions.py", line 64, in __call__
    return _find_element(driver, self.locator)
  File "/Users/dan/opt/miniconda3/envs/AICore/lib/python3.9/site-packages/selenium/webdriver/support/expected_conditions.py", line 415, in _find_element
    raise e
  File "/Users/dan/opt/miniconda3/envs/AICore/lib/python3.9/site-packages/selenium/webdriver/support/expected_conditions.py", line 411, in _find_element
    return driver.find_element(*by)
  File "/Users/dan/opt/miniconda3/envs/AICore/lib/python3.9/site-packages/selenium/webdriver/remote/webdriver.py", line 976, in find_element
    return self.execute(Command.FIND_ELEMENT, {
  File "/Users/dan/opt/miniconda3/envs/AICore/lib/python3.9/site-packages/selenium/webdriver/remote/webdriver.py", line 321, in execute
    self.error_handler.check_response(response)
  File "/Users/dan/opt/miniconda3/envs/AICore/lib/python3.9/site-packages/selenium/webdriver/remote/errorhandler.py", line 242, in check_response
    raise exception_class(message, screen, stacktrace)
selenium.common.exceptions.NoSuchWindowException: Message: no such window: target window already closed
from unknown error: web view not found
  (Session info: chrome=96.0.4664.110)

2021-12-15 21:29:38,264 INFO     [<ipython-input-5-658bc5ec1534>:53] Initializing Scraper for Hong Kong
2021-12-15 21:29:38,396 INFO     [<ipython-input-5-658bc5ec1534>:90] Depart date changed to 2022-01-10
2021-12-15 21:29:38,397 INFO     [<ipython-input-5-658bc5ec1534>:94] Destination changed to HKG
2021-12-15 21:29:38,397 INFO     [<ipython-input-5-658bc5ec1534>:97] Return date changed to 2022-01-14
2021-12-15 21:29:45,105 INFO     [<ipython-input-5-658bc5ec1534>:151] Getting information on flights for Hong Kong
2021-12-15 21:30:44,875 INFO     [<ipython-input-5-658bc5ec1534>:53] Initializing Scraper for Lanzarotte
2021-12-15 21:30:44,958 INFO     [<ipython-input-5-658bc5ec1534>:90] Depart date changed to 2022-01-10
2021-12-15 21:30:44,958 INFO     [<ipython-input-5-658bc5ec1534>:94] Destination changed to ACE
2021-12-15 21:30:44,958 INFO     [<ipython-input-5-658bc5ec1534>:97] Return date changed to 2022-01-14
2021-12-15 21:30:48,805 INFO     [<ipython-input-5-658bc5ec1534>:151] Getting information on flights for Lanzarotte
2021-12-15 21:31:10,498 INFO     [<ipython-input-5-658bc5ec1534>:53] Initializing Scraper for Lanzarotte
2021-12-15 21:31:10,556 INFO     [<ipython-input-5-658bc5ec1534>:90] Depart date changed to 2022-01-10
2021-12-15 21:31:10,556 INFO     [<ipython-input-5-658bc5ec1534>:94] Destination changed to ACE
2021-12-15 21:31:10,556 INFO     [<ipython-input-5-658bc5ec1534>:97] Return date changed to 2022-01-14
2021-12-15 21:31:16,204 INFO     [<ipython-input-5-658bc5ec1534>:151] Getting information on flights for Lanzarotte
2021-12-16 19:27:21,867 INFO     [<ipython-input-1-8ba82b487c85>:53] Initializing Scraper for Lanzarotte
2021-12-16 19:27:22,171 INFO     [<ipython-input-1-8ba82b487c85>:90] Depart date changed to 2022-01-10
2021-12-16 19:27:22,171 INFO     [<ipython-input-1-8ba82b487c85>:94] Destination changed to ACE
2021-12-16 19:27:22,171 INFO     [<ipython-input-1-8ba82b487c85>:97] Return date changed to 2022-01-14
2021-12-16 19:27:26,667 INFO     [<ipython-input-1-8ba82b487c85>:151] Getting information on flights for Lanzarotte
2021-12-16 19:27:54,338 INFO     [<ipython-input-1-8ba82b487c85>:53] Initializing Scraper for Lanzarotte
2021-12-16 19:27:54,522 INFO     [<ipython-input-1-8ba82b487c85>:90] Depart date changed to 2022-01-10
2021-12-16 19:27:54,522 INFO     [<ipython-input-1-8ba82b487c85>:94] Destination changed to ACE
2021-12-16 19:27:54,522 INFO     [<ipython-input-1-8ba82b487c85>:97] Return date changed to 2022-01-14
2021-12-16 19:28:01,958 INFO     [<ipython-input-1-8ba82b487c85>:151] Getting information on flights for Lanzarotte
2021-12-16 19:29:03,338 ERROR    [<ipython-input-1-8ba82b487c85>:81] Message: 
Traceback (most recent call last):
  File "<ipython-input-1-8ba82b487c85>", line 198, in run
    thread.run()
  File "/Users/dan/opt/miniconda3/envs/AICore/lib/python3.9/threading.py", line 910, in run
    self._target(*self._args, **self._kwargs)
  File "<ipython-input-1-8ba82b487c85>", line 188, in _run_scrape
    scraper.scrape("2022-01-10", "2022-01-14")
  File "<ipython-input-1-8ba82b487c85>", line 175, in scrape
    self.get_flight_info_driver()
  File "<ipython-input-1-8ba82b487c85>", line 165, in get_flight_info_driver
    flight = self.get_flight_info(info)
  File "<ipython-input-1-8ba82b487c85>", line 108, in get_flight_info
    depart_times = info.find_elements(By.XPATH, LOCATORS_DICT['DEPART_TIMES'])
  File "/Users/dan/opt/miniconda3/envs/AICore/lib/python3.9/site-packages/selenium/webdriver/remote/webelement.py", line 684, in find_elements
    return self._execute(Command.FIND_CHILD_ELEMENTS,
  File "/Users/dan/opt/miniconda3/envs/AICore/lib/python3.9/site-packages/selenium/webdriver/remote/webelement.py", line 633, in _execute
    return self._parent.execute(command, params)
  File "/Users/dan/opt/miniconda3/envs/AICore/lib/python3.9/site-packages/selenium/webdriver/remote/webdriver.py", line 321, in execute
    self.error_handler.check_response(response)
  File "/Users/dan/opt/miniconda3/envs/AICore/lib/python3.9/site-packages/selenium/webdriver/remote/errorhandler.py", line 242, in check_response
    raise exception_class(message, screen, stacktrace)
selenium.common.exceptions.StaleElementReferenceException: Message: stale element reference: element is not attached to the page document
  (Session info: headless chrome=96.0.4664.110)


During handling of the above exception, another exception occurred:

Traceback (most recent call last):
  File "<ipython-input-1-8ba82b487c85>", line 74, in __bypass_cookies
    WebDriverWait(self.driver, 10).until(
  File "/Users/dan/opt/miniconda3/envs/AICore/lib/python3.9/site-packages/selenium/webdriver/support/wait.py", line 80, in until
    raise TimeoutException(message, screen, stacktrace)
selenium.common.exceptions.TimeoutException: Message: 

2021-12-16 19:43:09,248 ERROR    [<ipython-input-3-f7faea66b9fb>:81] Message: 
Traceback (most recent call last):
  File "<ipython-input-3-f7faea66b9fb>", line 74, in __bypass_cookies
    WebDriverWait(self.driver, 10).until(
  File "/Users/dan/opt/miniconda3/envs/AICore/lib/python3.9/site-packages/selenium/webdriver/support/wait.py", line 80, in until
    raise TimeoutException(message, screen, stacktrace)
selenium.common.exceptions.TimeoutException: Message: 

2021-12-16 19:43:09,404 ERROR    [<ipython-input-3-f7faea66b9fb>:81] Message: 
Traceback (most recent call last):
  File "<ipython-input-3-f7faea66b9fb>", line 74, in __bypass_cookies
    WebDriverWait(self.driver, 10).until(
  File "/Users/dan/opt/miniconda3/envs/AICore/lib/python3.9/site-packages/selenium/webdriver/support/wait.py", line 80, in until
    raise TimeoutException(message, screen, stacktrace)
selenium.common.exceptions.TimeoutException: Message: 

2021-12-16 19:43:09,620 ERROR    [<ipython-input-3-f7faea66b9fb>:81] Message: 
Traceback (most recent call last):
  File "<ipython-input-3-f7faea66b9fb>", line 74, in __bypass_cookies
    WebDriverWait(self.driver, 10).until(
  File "/Users/dan/opt/miniconda3/envs/AICore/lib/python3.9/site-packages/selenium/webdriver/support/wait.py", line 80, in until
    raise TimeoutException(message, screen, stacktrace)
selenium.common.exceptions.TimeoutException: Message: 

2021-12-16 19:43:09,808 ERROR    [<ipython-input-3-f7faea66b9fb>:81] Message: 
Traceback (most recent call last):
  File "<ipython-input-3-f7faea66b9fb>", line 74, in __bypass_cookies
    WebDriverWait(self.driver, 10).until(
  File "/Users/dan/opt/miniconda3/envs/AICore/lib/python3.9/site-packages/selenium/webdriver/support/wait.py", line 80, in until
    raise TimeoutException(message, screen, stacktrace)
selenium.common.exceptions.TimeoutException: Message: 

2021-12-16 19:43:10,100 ERROR    [<ipython-input-3-f7faea66b9fb>:81] Message: 
Traceback (most recent call last):
  File "<ipython-input-3-f7faea66b9fb>", line 74, in __bypass_cookies
    WebDriverWait(self.driver, 10).until(
  File "/Users/dan/opt/miniconda3/envs/AICore/lib/python3.9/site-packages/selenium/webdriver/support/wait.py", line 80, in until
    raise TimeoutException(message, screen, stacktrace)
selenium.common.exceptions.TimeoutException: Message: 

2021-12-16 19:43:10,176 ERROR    [<ipython-input-3-f7faea66b9fb>:81] Message: 
Traceback (most recent call last):
  File "<ipython-input-3-f7faea66b9fb>", line 74, in __bypass_cookies
    WebDriverWait(self.driver, 10).until(
  File "/Users/dan/opt/miniconda3/envs/AICore/lib/python3.9/site-packages/selenium/webdriver/support/wait.py", line 80, in until
    raise TimeoutException(message, screen, stacktrace)
selenium.common.exceptions.TimeoutException: Message: 

2021-12-16 19:43:10,586 ERROR    [<ipython-input-3-f7faea66b9fb>:81] Message: 
Traceback (most recent call last):
  File "<ipython-input-3-f7faea66b9fb>", line 74, in __bypass_cookies
    WebDriverWait(self.driver, 10).until(
  File "/Users/dan/opt/miniconda3/envs/AICore/lib/python3.9/site-packages/selenium/webdriver/support/wait.py", line 80, in until
    raise TimeoutException(message, screen, stacktrace)
selenium.common.exceptions.TimeoutException: Message: 

2021-12-16 19:43:10,896 ERROR    [<ipython-input-3-f7faea66b9fb>:81] Message: 
Traceback (most recent call last):
  File "<ipython-input-3-f7faea66b9fb>", line 74, in __bypass_cookies
    WebDriverWait(self.driver, 10).until(
  File "/Users/dan/opt/miniconda3/envs/AICore/lib/python3.9/site-packages/selenium/webdriver/support/wait.py", line 80, in until
    raise TimeoutException(message, screen, stacktrace)
selenium.common.exceptions.TimeoutException: Message: 

2021-12-16 19:43:11,174 ERROR    [<ipython-input-3-f7faea66b9fb>:81] Message: 
Traceback (most recent call last):
  File "<ipython-input-3-f7faea66b9fb>", line 74, in __bypass_cookies
    WebDriverWait(self.driver, 10).until(
  File "/Users/dan/opt/miniconda3/envs/AICore/lib/python3.9/site-packages/selenium/webdriver/support/wait.py", line 80, in until
    raise TimeoutException(message, screen, stacktrace)
selenium.common.exceptions.TimeoutException: Message: 

2021-12-16 19:43:11,436 ERROR    [<ipython-input-3-f7faea66b9fb>:81] Message: 
Traceback (most recent call last):
  File "<ipython-input-3-f7faea66b9fb>", line 74, in __bypass_cookies
    WebDriverWait(self.driver, 10).until(
  File "/Users/dan/opt/miniconda3/envs/AICore/lib/python3.9/site-packages/selenium/webdriver/support/wait.py", line 80, in until
    raise TimeoutException(message, screen, stacktrace)
selenium.common.exceptions.TimeoutException: Message: 

2021-12-16 19:43:11,468 ERROR    [<ipython-input-3-f7faea66b9fb>:81] Message: 
Traceback (most recent call last):
  File "<ipython-input-3-f7faea66b9fb>", line 74, in __bypass_cookies
    WebDriverWait(self.driver, 10).until(
  File "/Users/dan/opt/miniconda3/envs/AICore/lib/python3.9/site-packages/selenium/webdriver/support/wait.py", line 80, in until
    raise TimeoutException(message, screen, stacktrace)
selenium.common.exceptions.TimeoutException: Message: 

2021-12-16 19:43:11,562 ERROR    [<ipython-input-3-f7faea66b9fb>:81] Message: 
Traceback (most recent call last):
  File "<ipython-input-3-f7faea66b9fb>", line 74, in __bypass_cookies
    WebDriverWait(self.driver, 10).until(
  File "/Users/dan/opt/miniconda3/envs/AICore/lib/python3.9/site-packages/selenium/webdriver/support/wait.py", line 80, in until
    raise TimeoutException(message, screen, stacktrace)
selenium.common.exceptions.TimeoutException: Message: 

2021-12-16 19:43:11,797 ERROR    [<ipython-input-3-f7faea66b9fb>:81] Message: 
Traceback (most recent call last):
  File "<ipython-input-3-f7faea66b9fb>", line 74, in __bypass_cookies
    WebDriverWait(self.driver, 10).until(
  File "/Users/dan/opt/miniconda3/envs/AICore/lib/python3.9/site-packages/selenium/webdriver/support/wait.py", line 80, in until
    raise TimeoutException(message, screen, stacktrace)
selenium.common.exceptions.TimeoutException: Message: 

2021-12-16 19:43:12,792 ERROR    [<ipython-input-3-f7faea66b9fb>:81] Message: 
Traceback (most recent call last):
  File "<ipython-input-3-f7faea66b9fb>", line 74, in __bypass_cookies
    WebDriverWait(self.driver, 10).until(
  File "/Users/dan/opt/miniconda3/envs/AICore/lib/python3.9/site-packages/selenium/webdriver/support/wait.py", line 80, in until
    raise TimeoutException(message, screen, stacktrace)
selenium.common.exceptions.TimeoutException: Message: 

2021-12-16 19:43:13,077 ERROR    [<ipython-input-3-f7faea66b9fb>:81] Message: 
Traceback (most recent call last):
  File "<ipython-input-3-f7faea66b9fb>", line 74, in __bypass_cookies
    WebDriverWait(self.driver, 10).until(
  File "/Users/dan/opt/miniconda3/envs/AICore/lib/python3.9/site-packages/selenium/webdriver/support/wait.py", line 80, in until
    raise TimeoutException(message, screen, stacktrace)
selenium.common.exceptions.TimeoutException: Message: 

2021-12-16 19:43:13,159 ERROR    [<ipython-input-3-f7faea66b9fb>:81] Message: 
Traceback (most recent call last):
  File "<ipython-input-3-f7faea66b9fb>", line 74, in __bypass_cookies
    WebDriverWait(self.driver, 10).until(
  File "/Users/dan/opt/miniconda3/envs/AICore/lib/python3.9/site-packages/selenium/webdriver/support/wait.py", line 80, in until
    raise TimeoutException(message, screen, stacktrace)
selenium.common.exceptions.TimeoutException: Message: 

2021-12-16 19:43:13,195 ERROR    [<ipython-input-3-f7faea66b9fb>:81] Message: 
Traceback (most recent call last):
  File "<ipython-input-3-f7faea66b9fb>", line 74, in __bypass_cookies
    WebDriverWait(self.driver, 10).until(
  File "/Users/dan/opt/miniconda3/envs/AICore/lib/python3.9/site-packages/selenium/webdriver/support/wait.py", line 80, in until
    raise TimeoutException(message, screen, stacktrace)
selenium.common.exceptions.TimeoutException: Message: 

2021-12-16 19:43:13,316 ERROR    [<ipython-input-3-f7faea66b9fb>:81] Message: 
Traceback (most recent call last):
  File "<ipython-input-3-f7faea66b9fb>", line 74, in __bypass_cookies
    WebDriverWait(self.driver, 10).until(
  File "/Users/dan/opt/miniconda3/envs/AICore/lib/python3.9/site-packages/selenium/webdriver/support/wait.py", line 80, in until
    raise TimeoutException(message, screen, stacktrace)
selenium.common.exceptions.TimeoutException: Message: 

2021-12-16 19:43:13,521 ERROR    [<ipython-input-3-f7faea66b9fb>:81] Message: 
Traceback (most recent call last):
  File "<ipython-input-3-f7faea66b9fb>", line 74, in __bypass_cookies
    WebDriverWait(self.driver, 10).until(
  File "/Users/dan/opt/miniconda3/envs/AICore/lib/python3.9/site-packages/selenium/webdriver/support/wait.py", line 80, in until
    raise TimeoutException(message, screen, stacktrace)
selenium.common.exceptions.TimeoutException: Message: 

2021-12-16 19:43:14,338 ERROR    [<ipython-input-3-f7faea66b9fb>:81] Message: 
Traceback (most recent call last):
  File "<ipython-input-3-f7faea66b9fb>", line 74, in __bypass_cookies
    WebDriverWait(self.driver, 10).until(
  File "/Users/dan/opt/miniconda3/envs/AICore/lib/python3.9/site-packages/selenium/webdriver/support/wait.py", line 80, in until
    raise TimeoutException(message, screen, stacktrace)
selenium.common.exceptions.TimeoutException: Message: 

2021-12-16 19:43:14,342 ERROR    [<ipython-input-3-f7faea66b9fb>:81] Message: 
Traceback (most recent call last):
  File "<ipython-input-3-f7faea66b9fb>", line 74, in __bypass_cookies
    WebDriverWait(self.driver, 10).until(
  File "/Users/dan/opt/miniconda3/envs/AICore/lib/python3.9/site-packages/selenium/webdriver/support/wait.py", line 80, in until
    raise TimeoutException(message, screen, stacktrace)
selenium.common.exceptions.TimeoutException: Message: 

2021-12-16 19:43:14,353 ERROR    [<ipython-input-3-f7faea66b9fb>:81] Message: 
Traceback (most recent call last):
  File "<ipython-input-3-f7faea66b9fb>", line 74, in __bypass_cookies
    WebDriverWait(self.driver, 10).until(
  File "/Users/dan/opt/miniconda3/envs/AICore/lib/python3.9/site-packages/selenium/webdriver/support/wait.py", line 80, in until
    raise TimeoutException(message, screen, stacktrace)
selenium.common.exceptions.TimeoutException: Message: 

2021-12-16 19:43:14,360 ERROR    [<ipython-input-3-f7faea66b9fb>:81] Message: 
Traceback (most recent call last):
  File "<ipython-input-3-f7faea66b9fb>", line 74, in __bypass_cookies
    WebDriverWait(self.driver, 10).until(
  File "/Users/dan/opt/miniconda3/envs/AICore/lib/python3.9/site-packages/selenium/webdriver/support/wait.py", line 80, in until
    raise TimeoutException(message, screen, stacktrace)
selenium.common.exceptions.TimeoutException: Message: 

2021-12-16 19:43:14,377 ERROR    [<ipython-input-3-f7faea66b9fb>:81] Message: 
Traceback (most recent call last):
  File "<ipython-input-3-f7faea66b9fb>", line 74, in __bypass_cookies
    WebDriverWait(self.driver, 10).until(
  File "/Users/dan/opt/miniconda3/envs/AICore/lib/python3.9/site-packages/selenium/webdriver/support/wait.py", line 80, in until
    raise TimeoutException(message, screen, stacktrace)
selenium.common.exceptions.TimeoutException: Message: 

2021-12-16 19:43:14,389 ERROR    [<ipython-input-3-f7faea66b9fb>:81] Message: 
Traceback (most recent call last):
  File "<ipython-input-3-f7faea66b9fb>", line 74, in __bypass_cookies
    WebDriverWait(self.driver, 10).until(
  File "/Users/dan/opt/miniconda3/envs/AICore/lib/python3.9/site-packages/selenium/webdriver/support/wait.py", line 80, in until
    raise TimeoutException(message, screen, stacktrace)
selenium.common.exceptions.TimeoutException: Message: 

2021-12-16 19:43:14,428 ERROR    [<ipython-input-3-f7faea66b9fb>:81] Message: 
Traceback (most recent call last):
  File "<ipython-input-3-f7faea66b9fb>", line 74, in __bypass_cookies
    WebDriverWait(self.driver, 10).until(
  File "/Users/dan/opt/miniconda3/envs/AICore/lib/python3.9/site-packages/selenium/webdriver/support/wait.py", line 80, in until
    raise TimeoutException(message, screen, stacktrace)
selenium.common.exceptions.TimeoutException: Message: 

2021-12-16 19:43:14,433 ERROR    [<ipython-input-3-f7faea66b9fb>:81] Message: 
Traceback (most recent call last):
  File "<ipython-input-3-f7faea66b9fb>", line 74, in __bypass_cookies
    WebDriverWait(self.driver, 10).until(
  File "/Users/dan/opt/miniconda3/envs/AICore/lib/python3.9/site-packages/selenium/webdriver/support/wait.py", line 80, in until
    raise TimeoutException(message, screen, stacktrace)
selenium.common.exceptions.TimeoutException: Message: 

2021-12-16 19:43:14,433 ERROR    [<ipython-input-3-f7faea66b9fb>:81] Message: 
Traceback (most recent call last):
  File "<ipython-input-3-f7faea66b9fb>", line 74, in __bypass_cookies
    WebDriverWait(self.driver, 10).until(
  File "/Users/dan/opt/miniconda3/envs/AICore/lib/python3.9/site-packages/selenium/webdriver/support/wait.py", line 80, in until
    raise TimeoutException(message, screen, stacktrace)
selenium.common.exceptions.TimeoutException: Message: 

2021-12-16 19:43:14,438 ERROR    [<ipython-input-3-f7faea66b9fb>:81] Message: 
Traceback (most recent call last):
  File "<ipython-input-3-f7faea66b9fb>", line 74, in __bypass_cookies
    WebDriverWait(self.driver, 10).until(
  File "/Users/dan/opt/miniconda3/envs/AICore/lib/python3.9/site-packages/selenium/webdriver/support/wait.py", line 80, in until
    raise TimeoutException(message, screen, stacktrace)
selenium.common.exceptions.TimeoutException: Message: 

2021-12-16 19:43:14,440 ERROR    [<ipython-input-3-f7faea66b9fb>:81] Message: 
Traceback (most recent call last):
  File "<ipython-input-3-f7faea66b9fb>", line 74, in __bypass_cookies
    WebDriverWait(self.driver, 10).until(
  File "/Users/dan/opt/miniconda3/envs/AICore/lib/python3.9/site-packages/selenium/webdriver/support/wait.py", line 80, in until
    raise TimeoutException(message, screen, stacktrace)
selenium.common.exceptions.TimeoutException: Message: 

2021-12-16 19:44:07,216 ERROR    [<ipython-input-1-d64e07356151>:81] Message: 
Traceback (most recent call last):
  File "<ipython-input-1-d64e07356151>", line 74, in __bypass_cookies
    WebDriverWait(self.driver, 10).until(
  File "/Users/dan/opt/miniconda3/envs/AICore/lib/python3.9/site-packages/selenium/webdriver/support/wait.py", line 80, in until
    raise TimeoutException(message, screen, stacktrace)
selenium.common.exceptions.TimeoutException: Message: 

2021-12-16 19:44:28,490 ERROR    [<ipython-input-1-d64e07356151>:81] Message: 
Traceback (most recent call last):
  File "<ipython-input-1-d64e07356151>", line 74, in __bypass_cookies
    WebDriverWait(self.driver, 10).until(
  File "/Users/dan/opt/miniconda3/envs/AICore/lib/python3.9/site-packages/selenium/webdriver/support/wait.py", line 80, in until
    raise TimeoutException(message, screen, stacktrace)
selenium.common.exceptions.TimeoutException: Message: 

2021-12-16 19:44:50,090 ERROR    [<ipython-input-1-d64e07356151>:81] Message: 
Traceback (most recent call last):
  File "<ipython-input-1-d64e07356151>", line 74, in __bypass_cookies
    WebDriverWait(self.driver, 10).until(
  File "/Users/dan/opt/miniconda3/envs/AICore/lib/python3.9/site-packages/selenium/webdriver/support/wait.py", line 80, in until
    raise TimeoutException(message, screen, stacktrace)
selenium.common.exceptions.TimeoutException: Message: 

2021-12-16 19:44:59,903 WARNING  [connectionpool.py:780] Retrying (Retry(total=2, connect=None, read=None, redirect=None, status=None)) after connection broken by 'NewConnectionError('<urllib3.connection.HTTPConnection object at 0x7fa428be2b80>: Failed to establish a new connection: [Errno 61] Connection refused')': /session/734748cbbcd5c40566164199cee48d8c/element
2021-12-16 19:44:59,904 WARNING  [connectionpool.py:780] Retrying (Retry(total=1, connect=None, read=None, redirect=None, status=None)) after connection broken by 'NewConnectionError('<urllib3.connection.HTTPConnection object at 0x7fa428823730>: Failed to establish a new connection: [Errno 61] Connection refused')': /session/734748cbbcd5c40566164199cee48d8c/element
2021-12-16 19:44:59,905 WARNING  [connectionpool.py:780] Retrying (Retry(total=0, connect=None, read=None, redirect=None, status=None)) after connection broken by 'NewConnectionError('<urllib3.connection.HTTPConnection object at 0x7fa4288233a0>: Failed to establish a new connection: [Errno 61] Connection refused')': /session/734748cbbcd5c40566164199cee48d8c/element
2021-12-16 19:44:59,905 ERROR    [<ipython-input-1-d64e07356151>:81] HTTPConnectionPool(host='127.0.0.1', port=52385): Max retries exceeded with url: /session/734748cbbcd5c40566164199cee48d8c/element (Caused by NewConnectionError('<urllib3.connection.HTTPConnection object at 0x7fa428823430>: Failed to establish a new connection: [Errno 61] Connection refused'))
Traceback (most recent call last):
  File "/Users/dan/opt/miniconda3/envs/AICore/lib/python3.9/site-packages/urllib3/connection.py", line 174, in _new_conn
    conn = connection.create_connection(
  File "/Users/dan/opt/miniconda3/envs/AICore/lib/python3.9/site-packages/urllib3/util/connection.py", line 96, in create_connection
    raise err
  File "/Users/dan/opt/miniconda3/envs/AICore/lib/python3.9/site-packages/urllib3/util/connection.py", line 86, in create_connection
    sock.connect(sa)
ConnectionRefusedError: [Errno 61] Connection refused

During handling of the above exception, another exception occurred:

Traceback (most recent call last):
  File "/Users/dan/opt/miniconda3/envs/AICore/lib/python3.9/site-packages/urllib3/connectionpool.py", line 699, in urlopen
    httplib_response = self._make_request(
  File "/Users/dan/opt/miniconda3/envs/AICore/lib/python3.9/site-packages/urllib3/connectionpool.py", line 394, in _make_request
    conn.request(method, url, **httplib_request_kw)
  File "/Users/dan/opt/miniconda3/envs/AICore/lib/python3.9/site-packages/urllib3/connection.py", line 239, in request
    super(HTTPConnection, self).request(method, url, body=body, headers=headers)
  File "/Users/dan/opt/miniconda3/envs/AICore/lib/python3.9/http/client.py", line 1279, in request
    self._send_request(method, url, body, headers, encode_chunked)
  File "/Users/dan/opt/miniconda3/envs/AICore/lib/python3.9/http/client.py", line 1325, in _send_request
    self.endheaders(body, encode_chunked=encode_chunked)
  File "/Users/dan/opt/miniconda3/envs/AICore/lib/python3.9/http/client.py", line 1274, in endheaders
    self._send_output(message_body, encode_chunked=encode_chunked)
  File "/Users/dan/opt/miniconda3/envs/AICore/lib/python3.9/http/client.py", line 1034, in _send_output
    self.send(msg)
  File "/Users/dan/opt/miniconda3/envs/AICore/lib/python3.9/http/client.py", line 974, in send
    self.connect()
  File "/Users/dan/opt/miniconda3/envs/AICore/lib/python3.9/site-packages/urllib3/connection.py", line 205, in connect
    conn = self._new_conn()
  File "/Users/dan/opt/miniconda3/envs/AICore/lib/python3.9/site-packages/urllib3/connection.py", line 186, in _new_conn
    raise NewConnectionError(
urllib3.exceptions.NewConnectionError: <urllib3.connection.HTTPConnection object at 0x7fa428823430>: Failed to establish a new connection: [Errno 61] Connection refused

During handling of the above exception, another exception occurred:

Traceback (most recent call last):
  File "<ipython-input-1-d64e07356151>", line 74, in __bypass_cookies
  File "/Users/dan/opt/miniconda3/envs/AICore/lib/python3.9/site-packages/selenium/webdriver/support/wait.py", line 71, in until
    value = method(self._driver)
  File "/Users/dan/opt/miniconda3/envs/AICore/lib/python3.9/site-packages/selenium/webdriver/support/expected_conditions.py", line 64, in __call__
    return _find_element(driver, self.locator)
  File "/Users/dan/opt/miniconda3/envs/AICore/lib/python3.9/site-packages/selenium/webdriver/support/expected_conditions.py", line 411, in _find_element
    return driver.find_element(*by)
  File "/Users/dan/opt/miniconda3/envs/AICore/lib/python3.9/site-packages/selenium/webdriver/remote/webdriver.py", line 976, in find_element
    return self.execute(Command.FIND_ELEMENT, {
  File "/Users/dan/opt/miniconda3/envs/AICore/lib/python3.9/site-packages/selenium/webdriver/remote/webdriver.py", line 319, in execute
    response = self.command_executor.execute(driver_command, params)
  File "/Users/dan/opt/miniconda3/envs/AICore/lib/python3.9/site-packages/selenium/webdriver/remote/remote_connection.py", line 374, in execute
    return self._request(command_info[0], url, body=data)
  File "/Users/dan/opt/miniconda3/envs/AICore/lib/python3.9/site-packages/selenium/webdriver/remote/remote_connection.py", line 397, in _request
    resp = self._conn.request(method, url, body=body, headers=headers)
  File "/Users/dan/opt/miniconda3/envs/AICore/lib/python3.9/site-packages/urllib3/request.py", line 78, in request
    return self.request_encode_body(
  File "/Users/dan/opt/miniconda3/envs/AICore/lib/python3.9/site-packages/urllib3/request.py", line 170, in request_encode_body
    return self.urlopen(method, url, **extra_kw)
  File "/Users/dan/opt/miniconda3/envs/AICore/lib/python3.9/site-packages/urllib3/poolmanager.py", line 375, in urlopen
    response = conn.urlopen(method, u.request_uri, **kw)
  File "/Users/dan/opt/miniconda3/envs/AICore/lib/python3.9/site-packages/urllib3/connectionpool.py", line 783, in urlopen
    return self.urlopen(
  File "/Users/dan/opt/miniconda3/envs/AICore/lib/python3.9/site-packages/urllib3/connectionpool.py", line 783, in urlopen
    return self.urlopen(
  File "/Users/dan/opt/miniconda3/envs/AICore/lib/python3.9/site-packages/urllib3/connectionpool.py", line 783, in urlopen
    return self.urlopen(
  File "/Users/dan/opt/miniconda3/envs/AICore/lib/python3.9/site-packages/urllib3/connectionpool.py", line 755, in urlopen
    retries = retries.increment(
  File "/Users/dan/opt/miniconda3/envs/AICore/lib/python3.9/site-packages/urllib3/util/retry.py", line 574, in increment
    raise MaxRetryError(_pool, url, error or ResponseError(cause))
urllib3.exceptions.MaxRetryError: HTTPConnectionPool(host='127.0.0.1', port=52385): Max retries exceeded with url: /session/734748cbbcd5c40566164199cee48d8c/element (Caused by NewConnectionError('<urllib3.connection.HTTPConnection object at 0x7fa428823430>: Failed to establish a new connection: [Errno 61] Connection refused'))
2021-12-16 19:44:59,910 WARNING  [connectionpool.py:780] Retrying (Retry(total=2, connect=None, read=None, redirect=None, status=None)) after connection broken by 'NewConnectionError('<urllib3.connection.HTTPConnection object at 0x7fa428823190>: Failed to establish a new connection: [Errno 61] Connection refused')': /session/734748cbbcd5c40566164199cee48d8c/element
2021-12-16 19:44:59,911 WARNING  [connectionpool.py:780] Retrying (Retry(total=1, connect=None, read=None, redirect=None, status=None)) after connection broken by 'NewConnectionError('<urllib3.connection.HTTPConnection object at 0x7fa3f845f490>: Failed to establish a new connection: [Errno 61] Connection refused')': /session/734748cbbcd5c40566164199cee48d8c/element
2021-12-16 19:44:59,911 WARNING  [connectionpool.py:780] Retrying (Retry(total=0, connect=None, read=None, redirect=None, status=None)) after connection broken by 'NewConnectionError('<urllib3.connection.HTTPConnection object at 0x7fa3f845f5b0>: Failed to establish a new connection: [Errno 61] Connection refused')': /session/734748cbbcd5c40566164199cee48d8c/element
2021-12-16 19:48:05,306 ERROR    [<ipython-input-2-1329e9388f2f>:81] Message: 
Traceback (most recent call last):
  File "<ipython-input-2-1329e9388f2f>", line 74, in __bypass_cookies
    WebDriverWait(self.driver, 10).until(
  File "/Users/dan/opt/miniconda3/envs/AICore/lib/python3.9/site-packages/selenium/webdriver/support/wait.py", line 80, in until
    raise TimeoutException(message, screen, stacktrace)
selenium.common.exceptions.TimeoutException: Message: 

2022-01-02 15:25:55,799 INFO     [<ipython-input-2-9acffe71280f>:57] Initializing Scraper for Bali
2022-01-02 15:25:56,755 INFO     [<ipython-input-2-9acffe71280f>:96] Depart date changed to 2022-01-10
2022-01-02 15:25:56,755 INFO     [<ipython-input-2-9acffe71280f>:100] Destination changed to DPS
2022-01-02 15:25:56,755 INFO     [<ipython-input-2-9acffe71280f>:103] Return date changed to 2022-01-14
2022-01-02 15:26:02,406 INFO     [<ipython-input-2-9acffe71280f>:155] Getting information on flights for Bali
2022-01-02 15:27:52,497 INFO     [<ipython-input-2-9acffe71280f>:57] Initializing Scraper for Las Vegas
2022-01-02 15:27:52,506 INFO     [<ipython-input-2-9acffe71280f>:96] Depart date changed to 2022-01-10
2022-01-02 15:27:52,506 INFO     [<ipython-input-2-9acffe71280f>:100] Destination changed to LAS
2022-01-02 15:27:52,506 INFO     [<ipython-input-2-9acffe71280f>:103] Return date changed to 2022-01-14
